Workbook

Sheet Export-dataset
A1: Year | B1: 0 Food and live animals ; | C1: 00 Live animals (excl. fish (not marine mammals) crustaceans, molluscs and aquatic invertebrates of SITC Division 03) ; | D1: 01 Meat and meat preparations ; | E1: 02 Dairy products and birds’ eggs ; | F1: 03 Fish (excl. marine mammals) crustaceans, molluscs and aquatic invertebrates, and preparations thereof (excl. extracts and juices of fish, crustaceans, molluscs or other aquatic invertebrates, prepared or preserved of SITC 01710) ; | G1: 04 Cereals and cereal preparations ; | H1: 05 Vegetables and fruit ; | I1: 06 Sugars, sugar preparations and honey ; | J1: 07 Coffee, tea, cocoa, spices, and manufactures thereof ; | K1: 08 Feeding stuff for animals (excl. unmilled cereals) ; | L1: 09 Miscellaneous edible products and preparations ; | M1: 1 Beverages and tobacco ; | N1: 11 Beverages ; | O1: 12 Tobacco and tobacco manufactures ; | P1: 2 Crude materials, inedible, except fuels ; | Q1: 21 Hides, skins and furskins, raw ; | R1: 22 Oil-seeds and oleaginous fruits ; | S1: 23 Crude rubber (incl. synthetic and reclaimed) ; | T1: 24 Cork and wood ; | U1: 25 Pulp and waste paper ; | V1: 26 Textile fibres (excl. wool tops and other combed wool) and their wastes, not manufactured into yarn or fabric ; | W1: 27 Crude fertilizers (excl. those of Division 56) and crude minerals (excl. coal, petroleum and precious stones) ; | X1: 28 Metalliferous ores and metal scrap ; | Y1: 29 Crude animal and vegetable materials, nes ; | Z1: 3 Mineral fuels, lubricants and related materials ; | AA1: 32 Coal, coke and briquettes ; | AB1: 33 Petroleum, petroleum products and related materials ; | AC1: 34 Gas, natural and manufactured ; | AD1: 4 Animal and vegetable oils, fats and waxes ; | AE1: 41 Animal oils and fats ; | AF1: 42 Fixed vegetable fats and oils, crude, refined or fractionated ; | AG1: 43 Animal or vegetable fats and oils, processed; waxes of animal or vegetable origin; inedible mixtures or preparations of animal or vegetable fats or oils, nes ; | AH1: 5 Chemicals and related products, nes ; | AI1: 51 Organic chemicals ; | AJ1: 52 Inorganic chemicals ; | AK1: 53 Dyeing, tanning and colouring materials ; | AL1: 54 Medicinal and pharmaceutical products ; | AM1: 55 Essential oils and resinoids and perfume materials; toilet, polishing and cleansing preparations ; | AN1: 56 Fertilisers (excl. those of group 272) ; | AO1: 57 Plastics in primary forms ; | AP1: 58 Plastics in non-primary forms ; | AQ1: 59 Chemical materials and products, nes ; | AR1: 6 Manufactured goods classified chiefly by material ; | AS1: 61 Leather, leather manufactures, nes, and dressed furskins ; | AT1: 62 Rubber manufactures, nes ; | AU1: 63 Cork and wood manufactures (excl. furniture) ; | AV1: 64 Paper, paperboard and articles of paper pulp, of paper or of paperboard ; | AW1: 65 Textile yarn, fabrics, made-up articles nes, and related products ; | AX1: 66 Non-metallic mineral manufactures, nes ; | AY1: 67 Iron and steel ; | AZ1: 68 Non-ferrous metals ; | BA1: 69 Manufactures of metals, nes ; | BB1: 7 Machinery and transport equipment ; | BC1: 71 Power generating machinery and equipment ; | BD1: 72 Machinery specialized for particular industries ; | BE1: 73 Metalworking machinery ; | BF1: 74 General industrial machinery and equipment, nes, and machine parts, nes ; | BG1: 75 Office machines and automatic data processing machines ; | BH1: 76 Telecommunications and sound recording and reproducing apparatus and equipment ; | BI1: 77 Electrical machinery, apparatus and appliances, nes, and electrical parts thereof (incl. non electrical counterparts, nes, of electrical household type equipment) ; | BJ1: 78 Road vehicles (incl. air-cushion vehicles) ; | BK1: 79 Transport equipment (excl. road vehicles) ; | BL1: 8 Miscellaneous manufactured articles ; | BM1: 81 Prefabricated buildings and sanitary, plumbing, heating and lighting fixtures and fittings, nes ; | BN1: 82 Furniture and parts thereof; bedding, mattresses, mattress supports, cushions and similar stuffed furnishings ; | BO1: 83 Travel goods, handbags and similar containers ; | BP1: 84 Articles of apparel and clothing accessories ; | BQ1: 85 Footwear ; | BR1: 87 Professional, scientific and controlling instruments and apparatus, nes ; | BS1: 88 Photographic apparatus, equipment and supplies and optical goods, nes; watches and clocks ; | BT1: 89 Miscellaneous manufactured articles, nes ; | BU1: 9 Commodities and transactions not classified elsewhere in the SITC ; | BV1: 93 Special transactions and commodities not classified according to kind ; | BW1: 95 Gold coin whether or not legal tender, and other coin being legal tender ; | BX1: 96 Coin (excl. gold coin) not being legal tender ; | BY1: 97 Gold, non-monetary (excl. gold ores and concentrates) ; | BZ1: 98 Combined confidential items excluding some of SITC 28099 (exports only) and some of SITC 51099 (imports only) ; | CA1: -1 TOTAL ;
A2: Y1988 | B2: 7908 | C2: 322 | D2: 2423 | E2: 529 | F2: 663 | G2: 2071 | H2: 604 | I2: 859 | J2: 68 | K2: 273 | L2: 91 | M2: 273 | N2: 250 | O2: 22 | P2: 13375 | Q2: 614 | R2: 63 | S2: 10 | T2: 439 | U2: 37 | V2: 6270 | W2: 221 | X2: 5595 | Y2: 124 | Z2: 6458 | AA2: 4636 | AB2: 1615 | AC2: 210 | AD2: 145 | AE2: 122 | AF2: 14 | AG2: 10 | AH2: 1041 | AI2: 102 | AJ2: 86 | AK2: 109 | AL2: 229 | AM2: 89 | AN2: 9 | AO2: 157 | AP2: 61 | AQ2: 199 | AR2: 5340 | AS2: 165 | AT2: 72 | AU2: 15 | AV2: 116 | AW2: 148 | AX2: 318 | AY2: 501 | AZ2: 3703 | BA2: 306 | BB2: 2742 | BC2: 366 | BD2: 336 | BE2: 39 | BF2: 322 | BG2: 406 | BH2: 142 | BI2: 280 | BJ2: 392 | BK2: 461 | BL2: 1077 | BM2: 31 | BN2: 36 | BO2: 2 | BP2: 65 | BQ2: 14 | BR2: 196 | BS2: 277 | BT2: 454 | BU2: 4003 | BV2: 156 | BW2: 196 | BX2: 1 | BY2: 2674 | BZ2: 979 | CA2: 42370
A3: Y1989 | B3: 9491 | C3: 244 | D3: 2639 | E3: 682 | F3: 646 | G3: 3205 | H3: 514 | I3: 1128 | J3: 65 | K3: 267 | L3: 97 | M3: 227 | N3: 211 | O3: 17 | P3: 14125 | Q3: 515 | R3: 44 | S3: 14 | T3: 409 | U3: 33 | V3: 5642 | W3: 206 | X3: 7128 | Y3: 133 | Z3: 7232 | AA3: 5314 | AB3: 1660 | AC3: 260 | AD3: 111 | AE3: 100 | AF3: 1 | AG3: 10 | AH3: 1175 | AI3: 90 | AJ3: 117 | AK3: 236 | AL3: 246 | AM3: 92 | AN3: 9 | AO3: 145 | AP3: 57 | AQ3: 182 | AR3: 6062 | AS3: 151 | AT3: 62 | AU3: 13 | AV3: 137 | AW3: 168 | AX3: 447 | AY3: 584 | AZ3: 4153 | BA3: 348 | BB3: 3286 | BC3: 378 | BD3: 382 | BE3: 54 | BF3: 351 | BG3: 480 | BH3: 219 | BI3: 327 | BJ3: 508 | BK3: 587 | BL3: 1261 | BM3: 28 | BN3: 35 | BO3: 3 | BP3: 88 | BQ3: 23 | BR3: 241 | BS3: 250 | BT3: 589 | BU3: 4036 | BV3: 153 | BW3: 205 | BX3: 0 | BY3: 2590 | BZ3: 1087 | CA3: 47007
A4: Y1990 | B4: 9726 | C4: 163 | D4: 3090 | E4: 676 | F4: 676 | G4: 3014 | H4: 581 | I4: 1101 | J4: 82 | K4: 238 | L4: 105 | M4: 285 | N4: 266 | O4: 19 | P4: 13459 | Q4: 528 | R4: 51 | S4: 8 | T4: 402 | U4: 21 | V4: 3939 | W4: 240 | X4: 8113 | Y4: 159 | Z4: 9594 | AA4: 6024 | AB4: 2882 | AC4: 690 | AD4: 131 | AE4: 113 | AF4: 1 | AG4: 12 | AH4: 1295 | AI4: 106 | AJ4: 175 | AK4: 221 | AL4: 293 | AM4: 105 | AN4: 12 | AO4: 136 | AP4: 76 | AQ4: 171 | AR4: 6257 | AS4: 180 | AT4: 67 | AU4: 33 | AV4: 168 | AW4: 196 | AX4: 464 | AY4: 909 | AZ4: 3833 | BA4: 407 | BB4: 4118 | BC4: 490 | BD4: 459 | BE4: 80 | BF4: 430 | BG4: 635 | BH4: 291 | BI4: 413 | BJ4: 736 | BK4: 583 | BL4: 1305 | BM4: 37 | BN4: 42 | BO4: 5 | BP4: 125 | BQ4: 22 | BR4: 252 | BS4: 241 | BT4: 582 | BU4: 4722 | BV4: 186 | BW4: 250 | BX4: 2 | BY4: 3440 | BZ4: 845 | CA4: 50891
A5: Y1991 | B5: 9312 | C5: 182 | D5: 3239 | E5: 793 | F5: 739 | G5: 2411 | H5: 651 | I5: 765 | J5: 92 | K5: 304 | L5: 135 | M5: 332 | N5: 313 | O5: 21 | P5: 13677 | Q5: 346 | R5: 59 | S5: 8 | T5: 461 | U5: 20 | V5: 4371 | W5: 290 | X5: 7955 | Y5: 163 | Z5: 10879 | AA5: 6857 | AB5: 2915 | AC5: 1105 | AD5: 136 | AE5: 117 | AF5: 1 | AG5: 18 | AH5: 1534 | AI5: 106 | AJ5: 253 | AK5: 188 | AL5: 381 | AM5: 125 | AN5: 17 | AO5: 181 | AP5: 82 | AQ5: 198 | AR5: 6480 | AS5: 187 | AT5: 67 | AU5: 50 | AV5: 209 | AW5: 218 | AX5: 556 | AY5: 1027 | AZ5: 3621 | BA5: 549 | BB5: 4867 | BC5: 566 | BD5: 523 | BE5: 79 | BF5: 511 | BG5: 808 | BH5: 317 | BI5: 542 | BJ5: 820 | BK5: 696 | BL5: 1427 | BM5: 38 | BN5: 36 | BO5: 2 | BP5: 142 | BQ5: 30 | BR5: 311 | BS5: 260 | BT5: 604 | BU5: 5072 | BV5: 197 | BW5: 321 | BX5: 0 | BY5: 3702 | BZ5: 854 | CA5: 53721
A6: Y1992 | B6: 10584 | C6: 226 | D6: 3669 | E6: 957 | F6: 913 | G6: 2449 | H6: 825 | I6: 888 | J6: 112 | K6: 405 | L6: 141 | M6: 378 | N6: 355 | O6: 22 | P6: 13495 | Q6: 398 | R6: 61 | S6: 11 | T6: 419 | U6: 9 | V6: 4539 | W6: 328 | X6: 7539 | Y6: 193 | Z6: 11613 | AA6: 7345 | AB6: 3123 | AC6: 1144 | AD6: 157 | AE6: 131 | AF6: 1 | AG6: 22 | AH6: 1818 | AI6: 77 | AJ6: 195 | AK6: 297 | AL6: 517 | AM6: 155 | AN6: 15 | AO6: 192 | AP6: 94 | AQ6: 275 | AR6: 7078 | AS6: 259 | AT6: 98 | AU6: 61 | AV6: 247 | AW6: 268 | AX6: 603 | AY6: 1179 | AZ6: 3816 | BA6: 547 | BB6: 5720 | BC6: 614 | BD6: 629 | BE6: 95 | BF6: 618 | BG6: 904 | BH6: 401 | BI6: 656 | BJ6: 887 | BK6: 917 | BL6: 1778 | BM6: 91 | BN6: 45 | BO6: 4 | BP6: 175 | BQ6: 36 | BR6: 367 | BS6: 338 | BT6: 716 | BU6: 5759 | BV6: 203 | BW6: 289 | BX6: 0 | BY6: 4476 | BZ6: 791 | CA6: 58377
A7: Y1993 | B7: 12440 | C7: 289 | D7: 3958 | E7: 1169 | F7: 1058 | G7: 3102 | H7: 912 | I7: 1210 | J7: 146 | K7: 430 | L7: 161 | M7: 491 | N7: 457 | O7: 35 | P7: 12753 | Q7: 378 | R7: 84 | S7: 10 | T7: 531 | U7: 13 | V7: 3662 | W7: 370 | X7: 7499 | Y7: 206 | Z7: 11977 | AA7: 7798 | AB7: 2964 | AC7: 1221 | AD7: 212 | AE7: 173 | AF7: 2 | AG7: 34 | AH7: 2185 | AI7: 83 | AJ7: 221 | AK7: 354 | AL7: 639 | AM7: 191 | AN7: 14 | AO7: 211 | AP7: 111 | AQ7: 365 | AR7: 7572 | AS7: 327 | AT7: 117 | AU7: 88 | AV7: 253 | AW7: 355 | AX7: 580 | AY7: 1380 | AZ7: 3895 | BA7: 580 | BB7: 7019 | BC7: 624 | BD7: 801 | BE7: 97 | BF7: 817 | BG7: 1169 | BH7: 436 | BI7: 886 | BJ7: 1096 | BK7: 1094 | BL7: 1998 | BM7: 46 | BN7: 75 | BO7: 10 | BP7: 222 | BQ7: 52 | BR7: 388 | BS7: 445 | BT7: 762 | BU7: 6091 | BV7: 295 | BW7: 222 | BX7: 0 | BY7: 4683 | BZ7: 893 | CA7: 62739
A8: Y1994 | B8: 13395 | C8: 359 | D8: 3799 | E8: 1423 | F8: 1092 | G8: 3340 | H8: 926 | I8: 1672 | J8: 173 | K8: 403 | L8: 207 | M8: 532 | N8: 493 | O8: 38 | P8: 13074 | Q8: 452 | R8: 128 | S8: 12 | T8: 531 | U8: 27 | V8: 4287 | W8: 352 | X8: 7074 | Y8: 211 | Z8: 10675 | AA8: 6750 | AB8: 2705 | AC8: 1216 | AD8: 226 | AE8: 184 | AF8: 7 | AG8: 32 | AH8: 2468 | AI8: 85 | AJ8: 277 | AK8: 372 | AL8: 729 | AM8: 235 | AN8: 23 | AO8: 209 | AP8: 123 | AQ8: 414 | AR8: 8287 | AS8: 426 | AT8: 126 | AU8: 89 | AV8: 253 | AW8: 417 | AX8: 787 | AY8: 1505 | AZ8: 3994 | BA8: 683 | BB8: 7602 | BC8: 602 | BD8: 806 | BE8: 120 | BF8: 935 | BG8: 1509 | BH8: 689 | BI8: 1088 | BJ8: 1014 | BK8: 843 | BL8: 2233 | BM8: 48 | BN8: 75 | BO8: 13 | BP8: 288 | BQ8: 56 | BR8: 444 | BS8: 483 | BT8: 828 | BU8: 6287 | BV8: 381 | BW8: 246 | BX8: 0 | BY8: 4671 | BZ8: 983 | CA8: 64775
A9: Y1995 | B9: 13073 | C9: 576 | D9: 3539 | E9: 1495 | F9: 1160 | G9: 2689 | H9: 921 | I9: 1877 | J9: 181 | K9: 412 | L9: 223 | M9: 581 | N9: 542 | O9: 43 | P9: 14643 | Q9: 492 | R9: 122 | S9: 13 | T9: 647 | U9: 47 | V9: 4404 | W9: 427 | X9: 8270 | Y9: 225 | Z9: 11976 | AA9: 7433 | AB9: 3029 | AC9: 1518 | AD9: 256 | AE9: 216 | AF9: 2 | AG9: 38 | AH9: 2909 | AI9: 80 | AJ9: 356 | AK9: 425 | AL9: 834 | AM9: 279 | AN9: 29 | AO9: 340 | AP9: 159 | AQ9: 406 | AR9: 9789 | AS9: 504 | AT9: 151 | AU9: 103 | AV9: 280 | AW9: 518 | AX9: 680 | AY9: 1767 | AZ9: 5094 | BA9: 694 | BB9: 9163 | BC9: 799 | BD9: 1063 | BE9: 142 | BF9: 1015 | BG9: 1753 | BH9: 689 | BI9: 1359 | BJ9: 1126 | BK9: 1218 | BL9: 2495 | BM9: 65 | BN9: 86 | BO9: 12 | BP9: 302 | BQ9: 63 | BR9: 469 | BS9: 530 | BT9: 969 | BU9: 6785 | BV9: 424 | BW9: 163 | BX9: 0 | BY9: 5263 | BZ9: 935 | CA9: 71670
A10: Y1996 | B10: 15805 | C10: 659 | D10: 2892 | E10: 1760 | F10: 1050 | G10: 5761 | H10: 1084 | I10: 1649 | J10: 196 | K10: 500 | L10: 253 | M10: 738 | N10: 677 | O10: 63 | P10: 15021 | Q10: 496 | R10: 218 | S10: 12 | T10: 621 | U10: 14 | V10: 4285 | W10: 384 | X10: 8771 | Y10: 222 | Z10: 13002 | AA10: 7818 | AB10: 3508 | AC10: 1676 | AD10: 236 | AE10: 194 | AF10: 10 | AG10: 33 | AH10: 3000 | AI10: 91 | AJ10: 333 | AK10: 420 | AL10: 942 | AM10: 300 | AN10: 23 | AO10: 299 | AP10: 153 | AQ10: 440 | AR10: 9426 | AS10: 471 | AT10: 159 | AU10: 109 | AV10: 343 | AW10: 566 | AX10: 770 | AY10: 1623 | AZ10: 4619 | BA10: 769 | BB10: 9959 | BC10: 878 | BD10: 1089 | BE10: 200 | BF10: 1219 | BG10: 1781 | BH10: 655 | BI10: 1347 | BJ10: 1538 | BK10: 1248 | BL10: 2812 | BM10: 85 | BN10: 99 | BO10: 14 | BP10: 339 | BQ10: 64 | BR10: 596 | BS10: 578 | BT10: 1038 | BU10: 6988 | BV10: 508 | BW10: 126 | BX10: 0 | BY10: 5236 | BZ10: 1117 | CA10: 76982
A11: Y1997 | B11: 17201 | C11: 743 | D11: 3442 | E11: 1834 | F11: 1203 | G11: 6042 | H11: 1156 | I11: 1723 | J11: 193 | K11: 558 | L11: 303 | M11: 892 | N11: 835 | O11: 55 | P11: 17144 | Q11: 546 | R11: 255 | S11: 11 | T11: 683 | U11: 19 | V11: 5225 | W11: 383 | X11: 9801 | Y11: 227 | Z11: 14968 | AA11: 8821 | AB11: 4102 | AC11: 2043 | AD11: 270 | AE11: 196 | AF11: 30 | AG11: 44 | AH11: 3216 | AI11: 143 | AJ11: 328 | AK11: 439 | AL11: 1058 | AM11: 298 | AN11: 21 | AO11: 318 | AP11: 162 | AQ11: 446 | AR11: 9917 | AS11: 510 | AT11: 163 | AU11: 107 | AV11: 416 | AW11: 626 | AX11: 783 | AY11: 1666 | AZ11: 4897 | BA11: 749 | BB11: 11323 | BC11: 1035 | BD11: 1189 | BE11: 221 | BF11: 1146 | BG11: 1674 | BH11: 987 | BI11: 1262 | BJ11: 1869 | BK11: 1931 | BL11: 3054 | BM11: 87 | BN11: 97 | BO11: 14 | BP11: 376 | BQ11: 59 | BR11: 710 | BS11: 665 | BT11: 1043 | BU11: 6807 | BV11: 530 | BW11: 128 | BX11: 1 | BY11: 4923 | BZ11: 1220 | CA11: 84790
A12: Y1998 | B12: 15156 | C12: 567 | D12: 3911 | E12: 2142 | F12: 1178 | G12: 5017 | H12: 1135 | I12: 180 | J12: 176 | K12: 545 | L12: 301 | M12: 1156 | N12: 1084 | O12: 70 | P12: 17909 | Q12: 510 | R12: 452 | S12: 10 | T12: 699 | U12: 22 | V12: 4503 | W12: 449 | X12: 11015 | Y12: 248 | Z12: 15077 | AA12: 9849 | AB12: 3374 | AC12: 1855 | AD12: 385 | AE12: 265 | AF12: 70 | AG12: 50 | AH12: 3387 | AI12: 139 | AJ12: 316 | AK12: 525 | AL12: 1225 | AM12: 283 | AN12: 32 | AO12: 237 | AP12: 164 | AQ12: 467 | AR12: 10423 | AS12: 497 | AT12: 169 | AU12: 104 | AV12: 421 | AW12: 593 | AX12: 698 | AY12: 1826 | AZ12: 5418 | BA12: 702 | BB12: 10654 | BC12: 808 | BD12: 1365 | BE12: 181 | BF12: 1034 | BG12: 1565 | BH12: 862 | BI12: 1277 | BJ12: 1863 | BK12: 1701 | BL12: 3342 | BM12: 85 | BN12: 98 | BO12: 12 | BP12: 365 | BQ12: 62 | BR12: 872 | BS12: 671 | BT12: 1180 | BU12: 11495 | BV12: 766 | BW12: 135 | BX12: 2 | BY12: 7642 | BZ12: 2948 | CA12: 88987
A13: Y1999 | B13: 15876 | C13: 698 | D13: 4163 | E13: 2209 | F13: 1387 | G13: 4882 | H13: 1192 | I13: 164 | J13: 213 | K13: 626 | L13: 344 | M13: 1402 | N13: 1345 | O13: 57 | P13: 16667 | Q13: 343 | R13: 777 | S13: 13 | T13: 698 | U13: 30 | V13: 3972 | W13: 415 | X13: 10164 | Y13: 257 | Z13: 14464 | AA13: 8406 | AB13: 4174 | AC13: 1880 | AD13: 324 | AE13: 226 | AF13: 51 | AG13: 51 | AH13: 3854 | AI13: 159 | AJ13: 380 | AK13: 524 | AL13: 1481 | AM13: 334 | AN13: 31 | AO13: 232 | AP13: 178 | AQ13: 536 | AR13: 10678 | AS13: 430 | AT13: 180 | AU13: 138 | AV13: 470 | AW13: 604 | AX13: 868 | AY13: 1362 | AZ13: 5974 | BA13: 658 | BB13: 10987 | BC13: 793 | BD13: 1096 | BE13: 197 | BF13: 1029 | BG13: 1405 | BH13: 906 | BI13: 1298 | BJ13: 2441 | BK13: 1823 | BL13: 3624 | BM13: 77 | BN13: 127 | BO13: 12 | BP13: 331 | BQ13: 63 | BR13: 1004 | BS13: 784 | BT13: 1220 | BU13: 9016 | BV13: 1807 | BW13: 98 | BX13: 8 | BY13: 4810 | BZ13: 2295 | CA13: 86893
... A38: Y2024 | B38: 52718 | C38: 1114 | D38: 21379 | E38: 3437 | F38: 1227 | G38: 13754 | H38: 7127 | I38: 299 | J38: 549 | K38: 1578 | L38: 2257 | M38: 3187 | N38: 3167 | O38: 20 | P38: 179557 | Q38: 534 | R38: 5001 | S38: 20 | T38: 1435 | U38: 243 | V38: 6501 | W38: 5157 | X38: 160031 | Y38: 637 | Z38: 171431 | AA38: 85981 | AB38: 15733 | AC38: 69718 | AD38: 1400 | AE38: 866 | AF38: 417 | AG38: 118 | AH38: 12289 | AI38: 215 | AJ38: 948 | AK38: 1163 | AL38: 5388 | AM38: 1709 | AN38: 437 | AO38: 295 | AP38: 412 | AQ38: 1724 | AR38: 20559 | AS38: 112 | AT38: 333 | AU38: 98 | AV38: 894 | AW38: 392 | AX38: 591 | AY38: 1328 | AZ38: 15335 | BA38: 1478 | BB38: 20549 | BC38: 1380 | BD38: 2355 | BE38: 287 | BF38: 3128 | BG38: 1582 | BH38: 2928 | BI38: 3233 | BJ38: 2281 | BK38: 3381 | BL38: 11000 | BM38: 193 | BN38: 170 | BO38: 178 | BP38: 774 | BQ38: 191 | BR38: 4087 | BS38: 611 | BT38: 4795 | BU38: 45165 | BV38: 566 | BW38: 1340 | BX38: 23 | BY38: 35703 | BZ38: 7534 | CA38: 517857
A39: Y2025 | B39: 0 Food and live animals ; | C39: 00 Live animals (excl. fish (not marine mammals) crustaceans, molluscs and aquatic invertebrates of SITC Division 03) ; | D39: 01 Meat and meat preparations ; | E39: 02 Dairy products and birds’ eggs ; | F39: 03 Fish (excl. marine mammals) crustaceans, molluscs and aquatic invertebrates, and preparations thereof (excl. extracts and juices of fish, crustaceans, molluscs or other aquatic invertebrates, prepared or preserved of SITC 01710) ; | G39: 04 Cereals and cereal preparations ; | H39: 05 Vegetables and fruit ; | I39: 06 Sugars, sugar preparations and honey ; | J39: 07 Coffee, tea, cocoa, spices, and manufactures thereof ; | K39: 08 Feeding stuff for animals (excl. unmilled cereals) ; | L39: 09 Miscellaneous edible products and preparations ; | M39: 1 Beverages and tobacco ; | N39: 11 Beverages ; | O39: 12 Tobacco and tobacco manufactures ; | P39: 2 Crude materials, inedible, except fuels ; | Q39: 21 Hides, skins and furskins, raw ; | R39: 22 Oil-seeds and oleaginous fruits ; | S39: 23 Crude rubber (incl. synthetic and reclaimed) ; | T39: 24 Cork and wood ; | U39: 25 Pulp and waste paper ; | V39: 26 Textile fibres (excl. wool tops and other combed wool) and their wastes, not manufactured into yarn or fabric ; | W39: 27 Crude fertilizers (excl. those of Division 56) and crude minerals (excl. coal, petroleum and precious stones) ; | X39: 28 Metalliferous ores and metal scrap ; | Y39: 29 Crude animal and vegetable materials, nes ; | Z39: 3 Mineral fuels, lubricants and related materials ; | AA39: 32 Coal, coke and briquettes ; | AB39: 33 Petroleum, petroleum products and related materials ; | AC39: 34 Gas, natural and manufactured ; | AD39: 4 Animal and vegetable oils, fats and waxes ; | AE39: 41 Animal oils and fats ; | AF39: 42 Fixed vegetable fats and oils, crude, refined or fractionated ; | AG39: 43 Animal or vegetable fats and oils, processed; waxes of animal or vegetable origin; inedible mixtures or preparations of animal or vegetable fats or oils, nes ; | AH39: 5 Chemicals and related products, nes ; | AI39: 51 Organic chemicals ; | AJ39: 52 Inorganic chemicals ; | AK39: 53 Dyeing, tanning and colouring materials ; | AL39: 54 Medicinal and pharmaceutical products ; | AM39: 55 Essential oils and resinoids and perfume materials; toilet, polishing and cleansing preparations ; | AN39: 56 Fertilisers (excl. those of group 272) ; | AO39: 57 Plastics in primary forms ; | AP39: 58 Plastics in non-primary forms ; | AQ39: 59 Chemical materials and products, nes ; | AR39: 6 Manufactured goods classified chiefly by material ; | AS39: 61 Leather, leather manufactures, nes, and dressed furskins ; | AT39: 62 Rubber manufactures, nes ; | AU39: 63 Cork and wood manufactures (excl. furniture) ; | AV39: 64 Paper, paperboard and articles of paper pulp, of paper or of paperboard ; | AW39: 65 Textile yarn, fabrics, made-up articles nes, and related products ; | AX39: 66 Non-metallic mineral manufactures, nes ; | AY39: 67 Iron and steel ; | AZ39: 68 Non-ferrous metals ; | BA39: 69 Manufactures of metals, nes ; | BB39: 7 Machinery and transport equipment ; | BC39: 71 Power generating machinery and equipment ; | BD39: 72 Machinery specialized for particular industries ; | BE39: 73 Metalworking machinery ; | BF39: 74 General industrial machinery and equipment, nes, and machine parts, nes ; | BG39: 75 Office machines and automatic data processing machines ; | BH39: 76 Telecommunications and sound recording and reproducing apparatus and equipment ; | BI39: 77 Electrical machinery, apparatus and appliances, nes, and electrical parts thereof (incl. non electrical counterparts, nes, of electrical household type equipment) ; | BJ39: 78 Road vehicles (incl. air-cushion vehicles) ; | BK39: 79 Transport equipment (excl. road vehicles) ; | BL39: 8 Miscellaneous manufactured articles ; | BM39: 81 Prefabricated buildings and sanitary, plumbing, heating and lighting fixtures and fittings, nes ; | BN39: 82 Furniture and parts thereof; bedding, mattresses, mattress supports, cushions and similar stuffed furnishings ; | BO39: 83 Travel goods, handbags and similar containers ; | BP39: 84 Articles of apparel and clothing accessories ; | BQ39: 85 Footwear ; | BR39: 87 Professional, scientific and controlling instruments and apparatus, nes ; | BS39: 88 Photographic apparatus, equipment and supplies and optical goods, nes; watches and clocks ; | BT39: 89 Miscellaneous manufactured articles, nes ; | BU39: 9 Commodities and transactions not classified elsewhere in the SITC ; | BV39: 93 Special transactions and commodities not classified according to kind ; | BW39: 95 Gold coin whether or not legal tender, and other coin being legal tender ; | BX39: 96 Coin (excl. gold coin) not being legal tender ; | BY39: 97 Gold, non-monetary (excl. gold ores and concentrates) ; | BZ39: 98 Combined confidential items excluding some of SITC 28099 (exports only) and some of SITC 51099 (imports only) ; | CA39: -1 TOTAL ;
A40: Y2026 | B40: =(B2/CA2)*100 -> 18.664149 | C40: =(C2/B2)*100 -> 4.071826 | D40: =(D2/B2)*100 -> 30.639858 | E40: =(E2/B2)*100 -> 6.6894284 | F40: =(F2/B2)*100 -> 8.383915 | G40: =(G2/B2)*100 -> 26.18867 | H40: =(H2/B2)*100 -> 7.6378351 | I40: =(I2/B2)*100 -> 10.862418 | J40: =(J2/B2)*100 -> 0.85988872 | K40: =(K2/B2)*100 -> 3.4522003 | L40: =(L2/B2)*100 -> 1.1507334 | M40: =(M2/CA2)*100 -> 0.64432381 | N40: =(N2/M2)*100 -> 91.575092 | O40: =(O2/M2)*100 -> 8.0586081 | P40: =(P2/CA2)*100 -> 31.567147 | Q40: =(Q2/P2)*100 -> 4.5906542 | R40: =(R2/P2)*100 -> 0.47102804 | S40: =(S2/P2)*100 -> 0.074766355 | T40: =(T2/P2)*100 -> 3.282243 | U40: =(U2/P2)*100 -> 0.27663551 | V40: =(V2/P2)*100 -> 46.878505 | W40: =(W2/P2)*100 -> 1.6523364 | X40: =(X2/P2)*100 -> 41.831776 | Y40: =(Y2/P2)*100 -> 0.9271028 | Z40: =(Z2/CA2)*100 -> 15.241916 | AA40: =(AA2/Z2)*100 -> 71.786931 | AB40: =(AB2/Z2)*100 -> 25.007742 | AC40: =(AC2/Z2)*100 -> 3.2517807 | AD40: =(AD2/CA2)*100 -> 0.34222327 | AE40: =(AE2/AD2)*100 -> 84.137931 | AF40: =(AF2/AD2)*100 -> 9.6551724 | AG40: =(AG2/AD2)*100 -> 6.8965517 | AH40: =(AH2/CA2)*100 -> 2.4569271 | AI40: =(AI2/AH2)*100 -> 9.7982709 | AJ40: =(AJ2/AH2)*100 -> 8.2612872 | AK40: =(AK2/AH2)*100 -> 10.470701 | AL40: =(AL2/AH2)*100 -> 21.998079 | AM40: =(AM2/AH2)*100 -> 8.5494717 | AN40: =(AN2/AH2)*100 -> 0.86455331 | AO40: =(AO2/AH2)*100 -> 15.081652 | AP40: =(AP2/AH2)*100 -> 5.8597502 | AQ40: =(AQ2/AH2)*100 -> 19.116234 | AR40: =(AR2/CA2)*100 -> 12.603257 | AS40: =(AS2/AR2)*100 -> 3.0898876 | AT40: =(AT2/AR2)*100 -> 1.3483146 | AU40: =(AU2/AR2)*100 -> 0.28089888 | AV40: =(AV2/AR2)*100 -> 2.1722846 | AW40: =(AW2/AR2)*100 -> 2.7715356 | AX40: =(AX2/AR2)*100 -> 5.9550562 | AY40: =(AY2/AR2)*100 -> 9.3820225 | AZ40: =(AZ2/AR2)*100 -> 69.344569 | BA40: =(BA2/AR2)*100 -> 5.7303371 | BB40: =(BB2/CA2)*100 -> 6.4715601 | BC40: =(BC2/BB2)*100 -> 13.347921 | BD40: =(BD2/BB2)*100 -> 12.253829 | BE40: =(BE2/BB2)*100 -> 1.4223195 | BF40: =(BF2/BB2)*100 -> 11.743253 | BG40: =(BG2/BB2)*100 -> 14.80671 | BH40: =(BH2/BB2)*100 -> 5.1787017 | BI40: =(BI2/BB2)*100 -> 10.211524 | BJ40: =(BJ2/BB2)*100 -> 14.296134 | BK40: =(BK2/BB2)*100 -> 16.812546 | BL40: =(BL2/CA2)*100 -> 2.5418928 | BM40: =(BM2/BL2)*100 -> 2.8783658 | BN40: =(BN2/BL2)*100 -> 3.3426184 | BO40: =(BO2/BL2)*100 -> 0.18570102 | BP40: =(BP2/BL2)*100 -> 6.0352832 | BQ40: =(BQ2/BL2)*100 -> 1.2999071 | BR40: =(BR2/BL2)*100 -> 18.1987 | BS40: =(BS2/BL2)*100 -> 25.719591 | BT40: =(BT2/BL2)*100 -> 42.154132 | BU40: =(BU2/CA2)*100 -> 9.4477224 | BV40: =(BV2/BU2)*100 -> 3.8970772 | BW40: =(BW2/BU2)*100 -> 4.8963278 | BX40: =(BX2/BU2)*100 -> 0.024981264 | BY40: =(BY2/BU2)*100 -> 66.7999 | BZ40: =(BZ2/BU2)*100 -> 24.456658
A41: Y2027 | B41: =(B3/CA3)*100 -> 20.19061 | C41: =(C3/B3)*100 -> 2.5708566 | D41: =(D3/B3)*100 -> 27.805289 | E41: =(E3/B3)*100 -> 7.1857549 | F41: =(F3/B3)*100 -> 6.8064482 | G41: =(G3/B3)*100 -> 33.768834 | H41: =(H3/B3)*100 -> 5.4156569 | I41: =(I3/B3)*100 -> 11.884944 | J41: =(J3/B3)*100 -> 0.68485934 | K41: =(K3/B3)*100 -> 2.8131914 | L41: =(L3/B3)*100 -> 1.0220209 | M41: =(M3/CA3)*100 -> 0.4829068 | N41: =(N3/M3)*100 -> 92.951542 | O41: =(O3/M3)*100 -> 7.4889868 | P41: =(P3/CA3)*100 -> 30.048716 | Q41: =(Q3/P3)*100 -> 3.6460177 | R41: =(R3/P3)*100 -> 0.31150442 | S41: =(S3/P3)*100 -> 0.099115044 | T41: =(T3/P3)*100 -> 2.8955752 | U41: =(U3/P3)*100 -> 0.23362832 | V41: =(V3/P3)*100 -> 39.943363 | W41: =(W3/P3)*100 -> 1.4584071 | X41: =(X3/P3)*100 -> 50.463717 | Y41: =(Y3/P3)*100 -> 0.94159292 | Z41: =(Z3/CA3)*100 -> 15.384943 | AA41: =(AA3/Z3)*100 -> 73.478982 | AB41: =(AB3/Z3)*100 -> 22.95354 | AC41: =(AC3/Z3)*100 -> 3.5951327 | AD41: =(AD3/CA3)*100 -> 0.23613504 | AE41: =(AE3/AD3)*100 -> 90.09009 | AF41: =(AF3/AD3)*100 -> 0.9009009 | AG41: =(AG3/AD3)*100 -> 9.009009 | AH41: =(AH3/CA3)*100 -> 2.4996277 | AI41: =(AI3/AH3)*100 -> 7.6595745 | AJ41: =(AJ3/AH3)*100 -> 9.9574468 | AK41: =(AK3/AH3)*100 -> 20.085106 | AL41: =(AL3/AH3)*100 -> 20.93617 | AM41: =(AM3/AH3)*100 -> 7.8297872 | AN41: =(AN3/AH3)*100 -> 0.76595745 | AO41: =(AO3/AH3)*100 -> 12.340426 | AP41: =(AP3/AH3)*100 -> 4.8510638 | AQ41: =(AQ3/AH3)*100 -> 15.489362 | AR41: =(AR3/CA3)*100 -> 12.895952 | AS41: =(AS3/AR3)*100 -> 2.4909271 | AT41: =(AT3/AR3)*100 -> 1.0227648 | AU41: =(AU3/AR3)*100 -> 0.21445068 | AV41: =(AV3/AR3)*100 -> 2.2599802 | AW41: =(AW3/AR3)*100 -> 2.7713626 | AX41: =(AX3/AR3)*100 -> 7.373804 | AY41: =(AY3/AR3)*100 -> 9.6337842 | AZ41: =(AZ3/AR3)*100 -> 68.508743 | BA41: =(BA3/AR3)*100 -> 5.7406796 | BB41: =(BB3/CA3)*100 -> 6.9904482 | BC41: =(BC3/BB3)*100 -> 11.503348 | BD41: =(BD3/BB3)*100 -> 11.625076 | BE41: =(BE3/BB3)*100 -> 1.6433354 | BF41: =(BF3/BB3)*100 -> 10.68168 | BG41: =(BG3/BB3)*100 -> 14.607425 | BH41: =(BH3/BB3)*100 -> 6.6646379 | BI41: =(BI3/BB3)*100 -> 9.9513086 | BJ41: =(BJ3/BB3)*100 -> 15.459525 | BK41: =(BK3/BB3)*100 -> 17.863664 | BL41: =(BL3/CA3)*100 -> 2.6825792 | BM41: =(BM3/BL3)*100 -> 2.22046 | BN41: =(BN3/BL3)*100 -> 2.7755749 | BO41: =(BO3/BL3)*100 -> 0.23790642 | BP41: =(BP3/BL3)*100 -> 6.9785884 | BQ41: =(BQ3/BL3)*100 -> 1.8239492 | BR41: =(BR3/BL3)*100 -> 19.111816 | BS41: =(BS3/BL3)*100 -> 19.825535 | BT41: =(BT3/BL3)*100 -> 46.708961 | BU41: =(BU3/CA3)*100 -> 8.5859553 | BV41: =(BV3/BU3)*100 -> 3.7908821 | BW41: =(BW3/BU3)*100 -> 5.0792864 | BX41: =(BX3/BU3)*100 -> 0 | BY41: =(BY3/BU3)*100 -> 64.172448 | BZ41: =(BZ3/BU3)*100 -> 26.932607
A42: Y2028 | B42: =(B4/CA4)*100 -> 19.111434 | C42: =(C4/B4)*100 -> 1.6759202 | D42: =(D4/B4)*100 -> 31.770512 | E42: =(E4/B4)*100 -> 6.9504421 | F42: =(F4/B4)*100 -> 6.9504421 | G42: =(G4/B4)*100 -> 30.989101 | H42: =(H4/B4)*100 -> 5.9736788 | I42: =(I4/B4)*100 -> 11.320173 | J42: =(J4/B4)*100 -> 0.84310097 | K42: =(K4/B4)*100 -> 2.4470491 | L42: =(L4/B4)*100 -> 1.0795805 | M42: =(M4/CA4)*100 -> 0.56002044 | N42: =(N4/M4)*100 -> 93.333333 | O42: =(O4/M4)*100 -> 6.6666667 | P42: =(P4/CA4)*100 -> 26.446719 | Q42: =(Q4/P4)*100 -> 3.9230255 | R42: =(R4/P4)*100 -> 0.3789286 | S42: =(S4/P4)*100 -> 0.05943978 | T42: =(T4/P4)*100 -> 2.9868489 | U42: =(U4/P4)*100 -> 0.15602942 | V42: =(V4/P4)*100 -> 29.266662 | W42: =(W4/P4)*100 -> 1.7831934 | X42: =(X4/P4)*100 -> 60.279367 | Y42: =(Y4/P4)*100 -> 1.1813656 | Z42: =(Z4/CA4)*100 -> 18.852056 | AA42: =(AA4/Z4)*100 -> 62.789243 | AB42: =(AB4/Z4)*100 -> 30.039608 | AC42: =(AC4/Z4)*100 -> 7.191995 | AD42: =(AD4/CA4)*100 -> 0.2574129 | AE42: =(AE4/AD4)*100 -> 86.259542 | AF42: =(AF4/AD4)*100 -> 0.76335878 | AG42: =(AG4/AD4)*100 -> 9.1603053 | AH42: =(AH4/CA4)*100 -> 2.5446543 | AI42: =(AI4/AH4)*100 -> 8.1853282 | AJ42: =(AJ4/AH4)*100 -> 13.513514 | AK42: =(AK4/AH4)*100 -> 17.065637 | AL42: =(AL4/AH4)*100 -> 22.625483 | AM42: =(AM4/AH4)*100 -> 8.1081081 | AN42: =(AN4/AH4)*100 -> 0.92664093 | AO42: =(AO4/AH4)*100 -> 10.501931 | AP42: =(AP4/AH4)*100 -> 5.8687259 | AQ42: =(AQ4/AH4)*100 -> 13.204633 | AR42: =(AR4/CA4)*100 -> 12.294905 | AS42: =(AS4/AR4)*100 -> 2.876778 | AT42: =(AT4/AR4)*100 -> 1.0708007 | AU42: =(AU4/AR4)*100 -> 0.5274093 | AV42: =(AV4/AR4)*100 -> 2.6849928 | AW42: =(AW4/AR4)*100 -> 3.1324916 | AX42: =(AX4/AR4)*100 -> 7.4156944 | AY42: =(AY4/AR4)*100 -> 14.527729 | AZ42: =(AZ4/AR4)*100 -> 61.259389 | BA42: =(BA4/AR4)*100 -> 6.5047147 | BB42: =(BB4/CA4)*100 -> 8.0918041 | BC42: =(BC4/BB4)*100 -> 11.89898 | BD42: =(BD4/BB4)*100 -> 11.146187 | BE42: =(BE4/BB4)*100 -> 1.9426906 | BF42: =(BF4/BB4)*100 -> 10.441962 | BG42: =(BG4/BB4)*100 -> 15.420107 | BH42: =(BH4/BB4)*100 -> 7.0665372 | BI42: =(BI4/BB4)*100 -> 10.02914 | BJ42: =(BJ4/BB4)*100 -> 17.872754 | BK42: =(BK4/BB4)*100 -> 14.157358 | BL42: =(BL4/CA4)*100 -> 2.5643041 | BM42: =(BM4/BL4)*100 -> 2.835249 | BN42: =(BN4/BL4)*100 -> 3.2183908 | BO42: =(BO4/BL4)*100 -> 0.38314176 | BP42: =(BP4/BL4)*100 -> 9.5785441 | BQ42: =(BQ4/BL4)*100 -> 1.6858238 | BR42: =(BR4/BL4)*100 -> 19.310345 | BS42: =(BS4/BL4)*100 -> 18.467433 | BT42: =(BT4/BL4)*100 -> 44.597701 | BU42: =(BU4/CA4)*100 -> 9.2786544 | BV42: =(BV4/BU4)*100 -> 3.9390089 | BW42: =(BW4/BU4)*100 -> 5.2943668 | BX42: =(BX4/BU4)*100 -> 0.042354934 | BY42: =(BY4/BU4)*100 -> 72.850487 | BZ42: =(BZ4/BU4)*100 -> 17.89496
A43: Y2029 | B43: =(B5/CA5)*100 -> 17.334003 | C43: =(C5/B5)*100 -> 1.9544674 | D43: =(D5/B5)*100 -> 34.783076 | E43: =(E5/B5)*100 -> 8.5158935 | F43: =(F5/B5)*100 -> 7.9359966 | G43: =(G5/B5)*100 -> 25.891323 | H43: =(H5/B5)*100 -> 6.9909794 | I43: =(I5/B5)*100 -> 8.2152062 | J43: =(J5/B5)*100 -> 0.98797251 | K43: =(K5/B5)*100 -> 3.2646048 | L43: =(L5/B5)*100 -> 1.4497423 | M43: =(M5/CA5)*100 -> 0.61800786 | N43: =(N5/M5)*100 -> 94.277108 | O43: =(O5/M5)*100 -> 6.3253012 | P43: =(P5/CA5)*100 -> 25.459318 | Q43: =(Q5/P5)*100 -> 2.5297945 | R43: =(R5/P5)*100 -> 0.43138115 | S43: =(S5/P5)*100 -> 0.058492359 | T43: =(T5/P5)*100 -> 3.3706222 | U43: =(U5/P5)*100 -> 0.1462309 | V43: =(V5/P5)*100 -> 31.958763 | W43: =(W5/P5)*100 -> 2.120348 | X43: =(X5/P5)*100 -> 58.16334 | Y43: =(Y5/P5)*100 -> 1.1917818 | Z43: =(Z5/CA5)*100 -> 20.250926 | AA43: =(AA5/Z5)*100 -> 63.02969 | AB43: =(AB5/Z5)*100 -> 26.794742 | AC43: =(AC5/Z5)*100 -> 10.157184 | AD43: =(AD5/CA5)*100 -> 0.25315984 | AE43: =(AE5/AD5)*100 -> 86.029412 | AF43: =(AF5/AD5)*100 -> 0.73529412 | AG43: =(AG5/AD5)*100 -> 13.235294 | AH43: =(AH5/CA5)*100 -> 2.8554941 | AI43: =(AI5/AH5)*100 -> 6.9100391 | AJ43: =(AJ5/AH5)*100 -> 16.492829 | AK43: =(AK5/AH5)*100 -> 12.255541 | AL43: =(AL5/AH5)*100 -> 24.837027 | AM43: =(AM5/AH5)*100 -> 8.148631 | AN43: =(AN5/AH5)*100 -> 1.1082138 | AO43: =(AO5/AH5)*100 -> 11.799218 | AP43: =(AP5/AH5)*100 -> 5.345502 | AQ43: =(AQ5/AH5)*100 -> 12.907432 | AR43: =(AR5/CA5)*100 -> 12.062322 | AS43: =(AS5/AR5)*100 -> 2.8858025 | AT43: =(AT5/AR5)*100 -> 1.0339506 | AU43: =(AU5/AR5)*100 -> 0.77160494 | AV43: =(AV5/AR5)*100 -> 3.2253086 | AW43: =(AW5/AR5)*100 -> 3.3641975 | AX43: =(AX5/AR5)*100 -> 8.5802469 | AY43: =(AY5/AR5)*100 -> 15.848765 | AZ43: =(AZ5/AR5)*100 -> 55.87963 | BA43: =(BA5/AR5)*100 -> 8.4722222 | BB43: =(BB5/CA5)*100 -> 9.0597718 | BC43: =(BC5/BB5)*100 -> 11.62934 | BD43: =(BD5/BB5)*100 -> 10.745839 | BE43: =(BE5/BB5)*100 -> 1.6231765 | BF43: =(BF5/BB5)*100 -> 10.499281 | BG43: =(BG5/BB5)*100 -> 16.601603 | BH43: =(BH5/BB5)*100 -> 6.5132525 | BI43: =(BI5/BB5)*100 -> 11.136224 | BJ43: =(BJ5/BB5)*100 -> 16.848161 | BK43: =(BK5/BB5)*100 -> 14.30039 | BL43: =(BL5/CA5)*100 -> 2.6563169 | BM43: =(BM5/BL5)*100 -> 2.6629292 | BN43: =(BN5/BL5)*100 -> 2.5227751 | BO43: =(BO5/BL5)*100 -> 0.14015417 | BP43: =(BP5/BL5)*100 -> 9.950946 | BQ43: =(BQ5/BL5)*100 -> 2.1023125 | BR43: =(BR5/BL5)*100 -> 21.793973 | BS43: =(BS5/BL5)*100 -> 18.220042 | BT43: =(BT5/BL5)*100 -> 42.326559 | BU43: =(BU5/CA5)*100 -> 9.441373 | BV43: =(BV5/BU5)*100 -> 3.8840694 | BW43: =(BW5/BU5)*100 -> 6.3288644 | BX43: =(BX5/BU5)*100 -> 0 | BY43: =(BY5/BU5)*100 -> 72.988959 | BZ43: =(BZ5/BU5)*100 -> 16.837539
A44: Y2030 | B44: =(B6/CA6)*100 -> 18.130428 | C44: =(C6/B6)*100 -> 2.1352986 | D44: =(D6/B6)*100 -> 34.665533 | E44: =(E6/B6)*100 -> 9.0419501 | F44: =(F6/B6)*100 -> 8.6262283 | G44: =(G6/B6)*100 -> 23.1387 | H44: =(H6/B6)*100 -> 7.7947846 | I44: =(I6/B6)*100 -> 8.3900227 | J44: =(J6/B6)*100 -> 1.0582011 | K44: =(K6/B6)*100 -> 3.8265306 | L44: =(L6/B6)*100 -> 1.3321995 | M44: =(M6/CA6)*100 -> 0.64751529 | N44: =(N6/M6)*100 -> 93.915344 | O44: =(O6/M6)*100 -> 5.8201058 | P44: =(P6/CA6)*100 -> 23.116981 | Q44: =(Q6/P6)*100 -> 2.9492405 | R44: =(R6/P6)*100 -> 0.45201927 | S44: =(S6/P6)*100 -> 0.081511671 | T44: =(T6/P6)*100 -> 3.1048536 | U44: =(U6/P6)*100 -> 0.066691367 | V44: =(V6/P6)*100 -> 33.63468 | W44: =(W6/P6)*100 -> 2.4305298 | X44: =(X6/P6)*100 -> 55.865135 | Y44: =(Y6/P6)*100 -> 1.4301593 | Z44: =(Z6/CA6)*100 -> 19.893109 | AA44: =(AA6/Z6)*100 -> 63.248084 | AB44: =(AB6/Z6)*100 -> 26.892276 | AC44: =(AC6/Z6)*100 -> 9.851029 | AD44: =(AD6/CA6)*100 -> 0.26894154 | AE44: =(AE6/AD6)*100 -> 83.43949 | AF44: =(AF6/AD6)*100 -> 0.63694268 | AG44: =(AG6/AD6)*100 -> 14.012739 | AH44: =(AH6/CA6)*100 -> 3.1142402 | AI44: =(AI6/AH6)*100 -> 4.2354235 | AJ44: =(AJ6/AH6)*100 -> 10.726073 | AK44: =(AK6/AH6)*100 -> 16.336634 | AL44: =(AL6/AH6)*100 -> 28.437844 | AM44: =(AM6/AH6)*100 -> 8.5258526 | AN44: =(AN6/AH6)*100 -> 0.82508251 | AO44: =(AO6/AH6)*100 -> 10.561056 | AP44: =(AP6/AH6)*100 -> 5.1705171 | AQ44: =(AQ6/AH6)*100 -> 15.126513 | AR44: =(AR6/CA6)*100 -> 12.124638 | AS44: =(AS6/AR6)*100 -> 3.6592258 | AT44: =(AT6/AR6)*100 -> 1.3845719 | AU44: =(AU6/AR6)*100 -> 0.86182537 | AV44: =(AV6/AR6)*100 -> 3.4896864 | AW44: =(AW6/AR6)*100 -> 3.7863803 | AX44: =(AX6/AR6)*100 -> 8.5193558 | AY44: =(AY6/AR6)*100 -> 16.657248 | AZ44: =(AZ6/AR6)*100 -> 53.913535 | BA44: =(BA6/AR6)*100 -> 7.7281718 | BB44: =(BB6/CA6)*100 -> 9.7983795 | BC44: =(BC6/BB6)*100 -> 10.734266 | BD44: =(BD6/BB6)*100 -> 10.996503 | BE44: =(BE6/BB6)*100 -> 1.6608392 | BF44: =(BF6/BB6)*100 -> 10.804196 | BG44: =(BG6/BB6)*100 -> 15.804196 | BH44: =(BH6/BB6)*100 -> 7.0104895 | BI44: =(BI6/BB6)*100 -> 11.468531 | BJ44: =(BJ6/BB6)*100 -> 15.506993 | BK44: =(BK6/BB6)*100 -> 16.031469 | BL44: =(BL6/CA6)*100 -> 3.0457201 | BM44: =(BM6/BL6)*100 -> 5.1181102 | BN44: =(BN6/BL6)*100 -> 2.5309336 | BO44: =(BO6/BL6)*100 -> 0.22497188 | BP44: =(BP6/BL6)*100 -> 9.8425197 | BQ44: =(BQ6/BL6)*100 -> 2.0247469 | BR44: =(BR6/BL6)*100 -> 20.64117 | BS44: =(BS6/BL6)*100 -> 19.010124 | BT44: =(BT6/BL6)*100 -> 40.269966 | BU44: =(BU6/CA6)*100 -> 9.8651866 | BV44: =(BV6/BU6)*100 -> 3.5249175 | BW44: =(BW6/BU6)*100 -> 5.0182323 | BX44: =(BX6/BU6)*100 -> 0 | BY44: =(BY6/BU6)*100 -> 77.721827 | BZ44: =(BZ6/BU6)*100 -> 13.735023
A45: Y2031 | B45: =(B7/CA7)*100 -> 19.828177 | C45: =(C7/B7)*100 -> 2.3231511 | D45: =(D7/B7)*100 -> 31.81672 | E45: =(E7/B7)*100 -> 9.3971061 | F45: =(F7/B7)*100 -> 8.5048232 | G45: =(G7/B7)*100 -> 24.935691 | H45: =(H7/B7)*100 -> 7.3311897 | I45: =(I7/B7)*100 -> 9.7266881 | J45: =(J7/B7)*100 -> 1.1736334 | K45: =(K7/B7)*100 -> 3.4565916 | L45: =(L7/B7)*100 -> 1.2942122 | M45: =(M7/CA7)*100 -> 0.78260731 | N45: =(N7/M7)*100 -> 93.075356 | O45: =(O7/M7)*100 -> 7.1283096 | P45: =(P7/CA7)*100 -> 20.327069 | Q45: =(Q7/P7)*100 -> 2.9640085 | R45: =(R7/P7)*100 -> 0.65866855 | S45: =(S7/P7)*100 -> 0.078412922 | T45: =(T7/P7)*100 -> 4.1637262 | U45: =(U7/P7)*100 -> 0.1019368 | V45: =(V7/P7)*100 -> 28.714812 | W45: =(W7/P7)*100 -> 2.9012781 | X45: =(X7/P7)*100 -> 58.801851 | Y45: =(Y7/P7)*100 -> 1.6153062 | Z45: =(Z7/CA7)*100 -> 19.090199 | AA45: =(AA7/Z7)*100 -> 65.108124 | AB45: =(AB7/Z7)*100 -> 24.747433 | AC45: =(AC7/Z7)*100 -> 10.19454 | AD45: =(AD7/CA7)*100 -> 0.33790784 | AE45: =(AE7/AD7)*100 -> 81.603774 | AF45: =(AF7/AD7)*100 -> 0.94339623 | AG45: =(AG7/AD7)*100 -> 16.037736 | AH45: =(AH7/CA7)*100 -> 3.4826822 | AI45: =(AI7/AH7)*100 -> 3.798627 | AJ45: =(AJ7/AH7)*100 -> 10.114416 | AK45: =(AK7/AH7)*100 -> 16.201373 | AL45: =(AL7/AH7)*100 -> 29.244851 | AM45: =(AM7/AH7)*100 -> 8.7414188 | AN45: =(AN7/AH7)*100 -> 0.64073227 | AO45: =(AO7/AH7)*100 -> 9.6567506 | AP45: =(AP7/AH7)*100 -> 5.0800915 | AQ45: =(AQ7/AH7)*100 -> 16.704805 | AR45: =(AR7/CA7)*100 -> 12.069048 | AS45: =(AS7/AR7)*100 -> 4.318542 | AT45: =(AT7/AR7)*100 -> 1.5451664 | AU45: =(AU7/AR7)*100 -> 1.1621764 | AV45: =(AV7/AR7)*100 -> 3.3412573 | AW45: =(AW7/AR7)*100 -> 4.6883254 | AX45: =(AX7/AR7)*100 -> 7.6597993 | AY45: =(AY7/AR7)*100 -> 18.22504 | AZ45: =(AZ7/AR7)*100 -> 51.439514 | BA45: =(BA7/AR7)*100 -> 7.6597993 | BB45: =(BB7/CA7)*100 -> 11.187619 | BC45: =(BC7/BB7)*100 -> 8.8901553 | BD45: =(BD7/BB7)*100 -> 11.411882 | BE45: =(BE7/BB7)*100 -> 1.3819632 | BF45: =(BF7/BB7)*100 -> 11.639835 | BG45: =(BG7/BB7)*100 -> 16.654794 | BH45: =(BH7/BB7)*100 -> 6.2117111 | BI45: =(BI7/BB7)*100 -> 12.622881 | BJ45: =(BJ7/BB7)*100 -> 15.61476 | BK45: =(BK7/BB7)*100 -> 15.586266 | BL45: =(BL7/CA7)*100 -> 3.184622 | BM45: =(BM7/BL7)*100 -> 2.3023023 | BN45: =(BN7/BL7)*100 -> 3.7537538 | BO45: =(BO7/BL7)*100 -> 0.5005005 | BP45: =(BP7/BL7)*100 -> 11.111111 | BQ45: =(BQ7/BL7)*100 -> 2.6026026 | BR45: =(BR7/BL7)*100 -> 19.419419 | BS45: =(BS7/BL7)*100 -> 22.272272 | BT45: =(BT7/BL7)*100 -> 38.138138 | BU45: =(BU7/CA7)*100 -> 9.7084748 | BV45: =(BV7/BU7)*100 -> 4.8432113 | BW45: =(BW7/BU7)*100 -> 3.6447217 | BX45: =(BX7/BU7)*100 -> 0 | BY45: =(BY7/BU7)*100 -> 76.883927 | BZ45: =(BZ7/BU7)*100 -> 14.660975
A46: Y2032 | B46: =(B8/CA8)*100 -> 20.679274 | C46: =(C8/B8)*100 -> 2.6801045 | D46: =(D8/B8)*100 -> 28.361329 | E46: =(E8/B8)*100 -> 10.623367 | F46: =(F8/B8)*100 -> 8.1522956 | G46: =(G8/B8)*100 -> 24.934677 | H46: =(H8/B8)*100 -> 6.9130272 | I46: =(I8/B8)*100 -> 12.48227 | J46: =(J8/B8)*100 -> 1.2915267 | K46: =(K8/B8)*100 -> 3.0085853 | L46: =(L8/B8)*100 -> 1.5453527 | M46: =(M8/CA8)*100 -> 0.82130452 | N46: =(N8/M8)*100 -> 92.669173 | O46: =(O8/M8)*100 -> 7.1428571 | P46: =(P8/CA8)*100 -> 20.183713 | Q46: =(Q8/P8)*100 -> 3.4572434 | R46: =(R8/P8)*100 -> 0.97904237 | S46: =(S8/P8)*100 -> 0.091785223 | T46: =(T8/P8)*100 -> 4.0614961 | U46: =(U8/P8)*100 -> 0.20651675 | V46: =(V8/P8)*100 -> 32.790271 | W46: =(W8/P8)*100 -> 2.6923665 | X46: =(X8/P8)*100 -> 54.107389 | Y46: =(Y8/P8)*100 -> 1.6138902 | Z46: =(Z8/CA8)*100 -> 16.480124 | AA46: =(AA8/Z8)*100 -> 63.23185 | AB46: =(AB8/Z8)*100 -> 25.339578 | AC46: =(AC8/Z8)*100 -> 11.391101 | AD46: =(AD8/CA8)*100 -> 0.34890004 | AE46: =(AE8/AD8)*100 -> 81.415929 | AF46: =(AF8/AD8)*100 -> 3.0973451 | AG46: =(AG8/AD8)*100 -> 14.159292 | AH46: =(AH8/CA8)*100 -> 3.8101119 | AI46: =(AI8/AH8)*100 -> 3.4440843 | AJ46: =(AJ8/AH8)*100 -> 11.223663 | AK46: =(AK8/AH8)*100 -> 15.072934 | AL46: =(AL8/AH8)*100 -> 29.538088 | AM46: =(AM8/AH8)*100 -> 9.5218801 | AN46: =(AN8/AH8)*100 -> 0.93192869 | AO46: =(AO8/AH8)*100 -> 8.4683955 | AP46: =(AP8/AH8)*100 -> 4.9837925 | AQ46: =(AQ8/AH8)*100 -> 16.774716 | AR46: =(AR8/CA8)*100 -> 12.793516 | AS46: =(AS8/AR8)*100 -> 5.1405816 | AT46: =(AT8/AR8)*100 -> 1.5204537 | AU46: =(AU8/AR8)*100 -> 1.0739713 | AV46: =(AV8/AR8)*100 -> 3.0529745 | AW46: =(AW8/AR8)*100 -> 5.0319778 | AX46: =(AX8/AR8)*100 -> 9.4968022 | AY46: =(AY8/AR8)*100 -> 18.160975 | AZ46: =(AZ8/AR8)*100 -> 48.19597 | BA46: =(BA8/AR8)*100 -> 8.2418245 | BB46: =(BB8/CA8)*100 -> 11.736009 | BC46: =(BC8/BB8)*100 -> 7.9189687 | BD46: =(BD8/BB8)*100 -> 10.602473 | BE46: =(BE8/BB8)*100 -> 1.578532 | BF46: =(BF8/BB8)*100 -> 12.299395 | BG46: =(BG8/BB8)*100 -> 19.850039 | BH46: =(BH8/BB8)*100 -> 9.0634044 | BI46: =(BI8/BB8)*100 -> 14.312023 | BJ46: =(BJ8/BB8)*100 -> 13.338595 | BK46: =(BK8/BB8)*100 -> 11.089187 | BL46: =(BL8/CA8)*100 -> 3.4473176 | BM46: =(BM8/BL8)*100 -> 2.1495746 | BN46: =(BN8/BL8)*100 -> 3.3587103 | BO46: =(BO8/BL8)*100 -> 0.58217644 | BP46: =(BP8/BL8)*100 -> 12.897447 | BQ46: =(BQ8/BL8)*100 -> 2.507837 | BR46: =(BR8/BL8)*100 -> 19.883565 | BS46: =(BS8/BL8)*100 -> 21.630094 | BT46: =(BT8/BL8)*100 -> 37.080161 | BU46: =(BU8/CA8)*100 -> 9.7059051 | BV46: =(BV8/BU8)*100 -> 6.0601241 | BW46: =(BW8/BU8)*100 -> 3.912836 | BX46: =(BX8/BU8)*100 -> 0 | BY46: =(BY8/BU8)*100 -> 74.296167 | BZ46: =(BZ8/BU8)*100 -> 15.635438
A47: Y2033 | B47: =(B9/CA9)*100 -> 18.240547 | C47: =(C9/B9)*100 -> 4.4060277 | D47: =(D9/B9)*100 -> 27.071062 | E47: =(E9/B9)*100 -> 11.435784 | F47: =(F9/B9)*100 -> 8.8732502 | G47: =(G9/B9)*100 -> 20.569112 | H47: =(H9/B9)*100 -> 7.0450547 | I47: =(I9/B9)*100 -> 14.357837 | J47: =(J9/B9)*100 -> 1.384533 | K47: =(K9/B9)*100 -> 3.1515337 | L47: =(L9/B9)*100 -> 1.7058059 | M47: =(M9/CA9)*100 -> 0.81065997 | N47: =(N9/M9)*100 -> 93.287435 | O47: =(O9/M9)*100 -> 7.4010327 | P47: =(P9/CA9)*100 -> 20.431143 | Q47: =(Q9/P9)*100 -> 3.3599672 | R47: =(R9/P9)*100 -> 0.8331626 | S47: =(S9/P9)*100 -> 0.088779622 | T47: =(T9/P9)*100 -> 4.4184935 | U47: =(U9/P9)*100 -> 0.32097248 | V47: =(V9/P9)*100 -> 30.075804 | W47: =(W9/P9)*100 -> 2.9160691 | X47: =(X9/P9)*100 -> 56.477498 | Y47: =(Y9/P9)*100 -> 1.5365704 | Z47: =(Z9/CA9)*100 -> 16.70992 | AA47: =(AA9/Z9)*100 -> 62.065798 | AB47: =(AB9/Z9)*100 -> 25.292251 | AC47: =(AC9/Z9)*100 -> 12.675351 | AD47: =(AD9/CA9)*100 -> 0.35719269 | AE47: =(AE9/AD9)*100 -> 84.375 | AF47: =(AF9/AD9)*100 -> 0.78125 | AG47: =(AG9/AD9)*100 -> 14.84375 | AH47: =(AH9/CA9)*100 -> 4.058881 | AI47: =(AI9/AH9)*100 -> 2.7500859 | AJ47: =(AJ9/AH9)*100 -> 12.237882 | AK47: =(AK9/AH9)*100 -> 14.609832 | AL47: =(AL9/AH9)*100 -> 28.669646 | AM47: =(AM9/AH9)*100 -> 9.5909247 | AN47: =(AN9/AH9)*100 -> 0.99690615 | AO47: =(AO9/AH9)*100 -> 11.687865 | AP47: =(AP9/AH9)*100 -> 5.4657958 | AQ47: =(AQ9/AH9)*100 -> 13.956686 | AR47: =(AR9/CA9)*100 -> 13.658434 | AS47: =(AS9/AR9)*100 -> 5.1486362 | AT47: =(AT9/AR9)*100 -> 1.5425478 | AU47: =(AU9/AR9)*100 -> 1.0522015 | AV47: =(AV9/AR9)*100 -> 2.8603535 | AW47: =(AW9/AR9)*100 -> 5.2916539 | AX47: =(AX9/AR9)*100 -> 6.9465727 | AY47: =(AY9/AR9)*100 -> 18.050873 | AZ47: =(AZ9/AR9)*100 -> 52.038002 | BA47: =(BA9/AR9)*100 -> 7.0895904 | BB47: =(BB9/CA9)*100 -> 12.784987 | BC47: =(BC9/BB9)*100 -> 8.7198516 | BD47: =(BD9/BB9)*100 -> 11.601004 | BE47: =(BE9/BB9)*100 -> 1.5497108 | BF47: =(BF9/BB9)*100 -> 11.077158 | BG47: =(BG9/BB9)*100 -> 19.131289 | BH47: =(BH9/BB9)*100 -> 7.5193714 | BI47: =(BI9/BB9)*100 -> 14.831387 | BJ47: =(BJ9/BB9)*100 -> 12.288552 | BK47: =(BK9/BB9)*100 -> 13.29259 | BL47: =(BL9/CA9)*100 -> 3.4812334 | BM47: =(BM9/BL9)*100 -> 2.6052104 | BN47: =(BN9/BL9)*100 -> 3.4468938 | BO47: =(BO9/BL9)*100 -> 0.48096192 | BP47: =(BP9/BL9)*100 -> 12.104208 | BQ47: =(BQ9/BL9)*100 -> 2.5250501 | BR47: =(BR9/BL9)*100 -> 18.797595 | BS47: =(BS9/BL9)*100 -> 21.242485 | BT47: =(BT9/BL9)*100 -> 38.837675 | BU47: =(BU9/CA9)*100 -> 9.4670015 | BV47: =(BV9/BU9)*100 -> 6.2490789 | BW47: =(BW9/BU9)*100 -> 2.4023581 | BX47: =(BX9/BU9)*100 -> 0 | BY47: =(BY9/BU9)*100 -> 77.568165 | BZ47: =(BZ9/BU9)*100 -> 13.780398
A48: Y2034 | B48: =(B10/CA10)*100 -> 20.530773 | C48: =(C10/B10)*100 -> 4.1695666 | D48: =(D10/B10)*100 -> 18.298007 | E48: =(E10/B10)*100 -> 11.135717 | F48: =(F10/B10)*100 -> 6.6434673 | G48: =(G10/B10)*100 -> 36.45049 | H48: =(H10/B10)*100 -> 6.8585891 | I48: =(I10/B10)*100 -> 10.433407 | J48: =(J10/B10)*100 -> 1.2401139 | K48: =(K10/B10)*100 -> 3.1635558 | L48: =(L10/B10)*100 -> 1.6007593 | M48: =(M10/CA10)*100 -> 0.95866566 | N48: =(N10/M10)*100 -> 91.734417 | O48: =(O10/M10)*100 -> 8.5365854 | P48: =(P10/CA10)*100 -> 19.512354 | Q48: =(Q10/P10)*100 -> 3.3020438 | R48: =(R10/P10)*100 -> 1.4513015 | S48: =(S10/P10)*100 -> 0.079888157 | T48: =(T10/P10)*100 -> 4.1342121 | U48: =(U10/P10)*100 -> 0.093202849 | V48: =(V10/P10)*100 -> 28.526729 | W48: =(W10/P10)*100 -> 2.556421 | X48: =(X10/P10)*100 -> 58.391585 | Y48: =(Y10/P10)*100 -> 1.4779309 | Z48: =(Z10/CA10)*100 -> 16.889663 | AA48: =(AA10/Z10)*100 -> 60.129211 | AB48: =(AB10/Z10)*100 -> 26.980465 | AC48: =(AC10/Z10)*100 -> 12.890325 | AD48: =(AD10/CA10)*100 -> 0.30656517 | AE48: =(AE10/AD10)*100 -> 82.20339 | AF48: =(AF10/AD10)*100 -> 4.2372881 | AG48: =(AG10/AD10)*100 -> 13.983051 | AH48: =(AH10/CA10)*100 -> 3.8970149 | AI48: =(AI10/AH10)*100 -> 3.0333333 | AJ48: =(AJ10/AH10)*100 -> 11.1 | AK48: =(AK10/AH10)*100 -> 14 | AL48: =(AL10/AH10)*100 -> 31.4 | AM48: =(AM10/AH10)*100 -> 10 | AN48: =(AN10/AH10)*100 -> 0.76666667 | AO48: =(AO10/AH10)*100 -> 9.9666667 | AP48: =(AP10/AH10)*100 -> 5.1 | AQ48: =(AQ10/AH10)*100 -> 14.666667 | AR48: =(AR10/CA10)*100 -> 12.244421 | AS48: =(AS10/AR10)*100 -> 4.9968173 | AT48: =(AT10/AR10)*100 -> 1.6868237 | AU48: =(AU10/AR10)*100 -> 1.156376 | AV48: =(AV10/AR10)*100 -> 3.6388712 | AW48: =(AW10/AR10)*100 -> 6.0046679 | AX48: =(AX10/AR10)*100 -> 8.1688945 | AY48: =(AY10/AR10)*100 -> 17.218332 | AZ48: =(AZ10/AR10)*100 -> 49.002758 | BA48: =(BA10/AR10)*100 -> 8.1582856 | BB48: =(BB10/CA10)*100 -> 12.93679 | BC48: =(BC10/BB10)*100 -> 8.8161462 | BD48: =(BD10/BB10)*100 -> 10.934833 | BE48: =(BE10/BB10)*100 -> 2.0082338 | BF48: =(BF10/BB10)*100 -> 12.240185 | BG48: =(BG10/BB10)*100 -> 17.883322 | BH48: =(BH10/BB10)*100 -> 6.5769656 | BI48: =(BI10/BB10)*100 -> 13.525454 | BJ48: =(BJ10/BB10)*100 -> 15.443318 | BK48: =(BK10/BB10)*100 -> 12.531379 | BL48: =(BL10/CA10)*100 -> 3.652802 | BM48: =(BM10/BL10)*100 -> 3.0227596 | BN48: =(BN10/BL10)*100 -> 3.5206259 | BO48: =(BO10/BL10)*100 -> 0.49786629 | BP48: =(BP10/BL10)*100 -> 12.055477 | BQ48: =(BQ10/BL10)*100 -> 2.2759602 | BR48: =(BR10/BL10)*100 -> 21.194879 | BS48: =(BS10/BL10)*100 -> 20.554765 | BT48: =(BT10/BL10)*100 -> 36.913229 | BU48: =(BU10/CA10)*100 -> 9.0774467 | BV48: =(BV10/BU10)*100 -> 7.269605 | BW48: =(BW10/BU10)*100 -> 1.803091 | BX48: =(BX10/BU10)*100 -> 0 | BY48: =(BY10/BU10)*100 -> 74.928449 | BZ48: =(BZ10/BU10)*100 -> 15.984545
A49: Y2035 | B49: =(B11/CA11)*100 -> 20.28659 | C49: =(C11/B11)*100 -> 4.3195163 | D49: =(D11/B11)*100 -> 20.010465 | E49: =(E11/B11)*100 -> 10.662171 | F49: =(F11/B11)*100 -> 6.9937794 | G49: =(G11/B11)*100 -> 35.125865 | H49: =(H11/B11)*100 -> 6.7205395 | I49: =(I11/B11)*100 -> 10.016859 | J49: =(J11/B11)*100 -> 1.1220278 | K49: =(K11/B11)*100 -> 3.2439974 | L49: =(L11/B11)*100 -> 1.7615255 | M49: =(M11/CA11)*100 -> 1.0520109 | N49: =(N11/M11)*100 -> 93.609865 | O49: =(O11/M11)*100 -> 6.1659193 | P49: =(P11/CA11)*100 -> 20.219365 | Q49: =(Q11/P11)*100 -> 3.1847877 | R49: =(R11/P11)*100 -> 1.4874008 | S49: =(S11/P11)*100 -> 0.064162389 | T49: =(T11/P11)*100 -> 3.9839011 | U49: =(U11/P11)*100 -> 0.11082594 | V49: =(V11/P11)*100 -> 30.477135 | W49: =(W11/P11)*100 -> 2.2340177 | X49: =(X11/P11)*100 -> 57.168689 | Y49: =(Y11/P11)*100 -> 1.3240784 | Z49: =(Z11/CA11)*100 -> 17.653025 | AA49: =(AA11/Z11)*100 -> 58.932389 | AB49: =(AB11/Z11)*100 -> 27.405131 | AC49: =(AC11/Z11)*100 -> 13.649118 | AD49: =(AD11/CA11)*100 -> 0.31843378 | AE49: =(AE11/AD11)*100 -> 72.592593 | AF49: =(AF11/AD11)*100 -> 11.111111 | AG49: =(AG11/AD11)*100 -> 16.296296 | AH49: =(AH11/CA11)*100 -> 3.7929001 | AI49: =(AI11/AH11)*100 -> 4.4465174 | AJ49: =(AJ11/AH11)*100 -> 10.199005 | AK49: =(AK11/AH11)*100 -> 13.650498 | AL49: =(AL11/AH11)*100 -> 32.89801 | AM49: =(AM11/AH11)*100 -> 9.2661692 | AN49: =(AN11/AH11)*100 -> 0.65298507 | AO49: =(AO11/AH11)*100 -> 9.8880597 | AP49: =(AP11/AH11)*100 -> 5.0373134 | AQ49: =(AQ11/AH11)*100 -> 13.868159 | AR49: =(AR11/CA11)*100 -> 11.695955 | AS49: =(AS11/AR11)*100 -> 5.1426843 | AT49: =(AT11/AR11)*100 -> 1.6436422 | AU49: =(AU11/AR11)*100 -> 1.0789553 | AV49: =(AV11/AR11)*100 -> 4.194817 | AW49: =(AW11/AR11)*100 -> 6.3123929 | AX49: =(AX11/AR11)*100 -> 7.8955329 | AY49: =(AY11/AR11)*100 -> 16.799435 | AZ49: =(AZ11/AR11)*100 -> 49.379853 | BA49: =(BA11/AR11)*100 -> 7.5526873 | BB49: =(BB11/CA11)*100 -> 13.354169 | BC49: =(BC11/BB11)*100 -> 9.1406871 | BD49: =(BD11/BB11)*100 -> 10.500751 | BE49: =(BE11/BB11)*100 -> 1.9517796 | BF49: =(BF11/BB11)*100 -> 10.120993 | BG49: =(BG11/BB11)*100 -> 14.784068 | BH49: =(BH11/BB11)*100 -> 8.7167712 | BI49: =(BI11/BB11)*100 -> 11.145456 | BJ49: =(BJ11/BB11)*100 -> 16.506226 | BK49: =(BK11/BB11)*100 -> 17.053784 | BL49: =(BL11/CA11)*100 -> 3.6018398 | BM49: =(BM11/BL11)*100 -> 2.848723 | BN49: =(BN11/BL11)*100 -> 3.1761624 | BO49: =(BO11/BL11)*100 -> 0.45841519 | BP49: =(BP11/BL11)*100 -> 12.311722 | BQ49: =(BQ11/BL11)*100 -> 1.9318926 | BR49: =(BR11/BL11)*100 -> 23.248199 | BS49: =(BS11/BL11)*100 -> 21.774722 | BT49: =(BT11/BL11)*100 -> 34.151932 | BU49: =(BU11/CA11)*100 -> 8.0280693 | BV49: =(BV11/BU11)*100 -> 7.7861025 | BW49: =(BW11/BU11)*100 -> 1.8804172 | BX49: =(BX11/BU11)*100 -> 0.01469076 | BY49: =(BY11/BU11)*100 -> 72.322609 | BZ49: =(BZ11/BU11)*100 -> 17.922727
A50: Y2036 | B50: =(B12/CA12)*100 -> 17.031701 | C50: =(C12/B12)*100 -> 3.7410926 | D50: =(D12/B12)*100 -> 25.804962 | E50: =(E12/B12)*100 -> 14.133017 | F50: =(F12/B12)*100 -> 7.7724993 | G50: =(G12/B12)*100 -> 33.102402 | H50: =(H12/B12)*100 -> 7.4887833 | I50: =(I12/B12)*100 -> 1.1876485 | J50: =(J12/B12)*100 -> 1.1612563 | K50: =(K12/B12)*100 -> 3.5959356 | L50: =(L12/B12)*100 -> 1.9860121 | M50: =(M12/CA12)*100 -> 1.2990662 | N50: =(N12/M12)*100 -> 93.771626 | O50: =(O12/M12)*100 -> 6.0553633 | P50: =(P12/CA12)*100 -> 20.125412 | Q50: =(Q12/P12)*100 -> 2.8477302 | R50: =(R12/P12)*100 -> 2.5238707 | S50: =(S12/P12)*100 -> 0.055837847 | T50: =(T12/P12)*100 -> 3.9030655 | U50: =(U12/P12)*100 -> 0.12284326 | V50: =(V12/P12)*100 -> 25.143782 | W50: =(W12/P12)*100 -> 2.5071193 | X50: =(X12/P12)*100 -> 61.505388 | Y50: =(Y12/P12)*100 -> 1.3847786 | Z50: =(Z12/CA12)*100 -> 16.942924 | AA50: =(AA12/Z12)*100 -> 65.324667 | AB50: =(AB12/Z12)*100 -> 22.378457 | AC50: =(AC12/Z12)*100 -> 12.303509 | AD50: =(AD12/CA12)*100 -> 0.43264747 | AE50: =(AE12/AD12)*100 -> 68.831169 | AF50: =(AF12/AD12)*100 -> 18.181818 | AG50: =(AG12/AD12)*100 -> 12.987013 | AH50: =(AH12/CA12)*100 -> 3.8061739 | AI50: =(AI12/AH12)*100 -> 4.1039268 | AJ50: =(AJ12/AH12)*100 -> 9.3297904 | AK50: =(AK12/AH12)*100 -> 15.500443 | AL50: =(AL12/AH12)*100 -> 36.1677 | AM50: =(AM12/AH12)*100 -> 8.3554768 | AN50: =(AN12/AH12)*100 -> 0.9447889 | AO50: =(AO12/AH12)*100 -> 6.9973428 | AP50: =(AP12/AH12)*100 -> 4.8420431 | AQ50: =(AQ12/AH12)*100 -> 13.788013 | AR50: =(AR12/CA12)*100 -> 11.712947 | AS50: =(AS12/AR12)*100 -> 4.7683009 | AT50: =(AT12/AR12)*100 -> 1.6214142 | AU50: =(AU12/AR12)*100 -> 0.99779334 | AV50: =(AV12/AR12)*100 -> 4.0391442 | AW50: =(AW12/AR12)*100 -> 5.6893409 | AX50: =(AX12/AR12)*100 -> 6.6967284 | AY50: =(AY12/AR12)*100 -> 17.518948 | AZ50: =(AZ12/AR12)*100 -> 51.981195 | BA50: =(BA12/AR12)*100 -> 6.7351051 | BB50: =(BB12/CA12)*100 -> 11.972535 | BC50: =(BC12/BB12)*100 -> 7.584006 | BD50: =(BD12/BB12)*100 -> 12.812089 | BE50: =(BE12/BB12)*100 -> 1.6988924 | BF50: =(BF12/BB12)*100 -> 9.705275 | BG50: =(BG12/BB12)*100 -> 14.689319 | BH50: =(BH12/BB12)*100 -> 8.0908579 | BI50: =(BI12/BB12)*100 -> 11.986109 | BJ50: =(BJ12/BB12)*100 -> 17.48639 | BK50: =(BK12/BB12)*100 -> 15.965834 | BL50: =(BL12/CA12)*100 -> 3.7556048 | BM50: =(BM12/BL12)*100 -> 2.5433872 | BN50: =(BN12/BL12)*100 -> 2.9323758 | BO50: =(BO12/BL12)*100 -> 0.35906643 | BP50: =(BP12/BL12)*100 -> 10.921604 | BQ50: =(BQ12/BL12)*100 -> 1.8551765 | BR50: =(BR12/BL12)*100 -> 26.09216 | BS50: =(BS12/BL12)*100 -> 20.077798 | BT50: =(BT12/BL12)*100 -> 35.308199 | BU50: =(BU12/CA12)*100 -> 12.917617 | BV50: =(BV12/BU12)*100 -> 6.6637669 | BW50: =(BW12/BU12)*100 -> 1.1744237 | BX50: =(BX12/BU12)*100 -> 0.017398869 | BY50: =(BY12/BU12)*100 -> 66.481079 | BZ50: =(BZ12/BU12)*100 -> 25.645933
A51: Y2037 | B51: =(B13/CA13)*100 -> 18.270747 | C51: =(C13/B13)*100 -> 4.3965734 | D51: =(D13/B13)*100 -> 26.22197 | E51: =(E13/B13)*100 -> 13.914084 | F51: =(F13/B13)*100 -> 8.7364575 | G51: =(G13/B13)*100 -> 30.750819 | H51: =(H13/B13)*100 -> 7.5081885 | I51: =(I13/B13)*100 -> 1.0330058 | J51: =(J13/B13)*100 -> 1.3416478 | K51: =(K13/B13)*100 -> 3.9430587 | L51: =(L13/B13)*100 -> 2.1667926 | M51: =(M13/CA13)*100 -> 1.6134786 | N51: =(N13/M13)*100 -> 95.934379 | O51: =(O13/M13)*100 -> 4.0656205 | P51: =(P13/CA13)*100 -> 19.181062 | Q51: =(Q13/P13)*100 -> 2.0579588 | R51: =(R13/P13)*100 -> 4.6619068 | S51: =(S13/P13)*100 -> 0.07799844 | T51: =(T13/P13)*100 -> 4.1879162 | U51: =(U13/P13)*100 -> 0.1799964 | V51: =(V13/P13)*100 -> 23.831523 | W51: =(W13/P13)*100 -> 2.4899502 | X51: =(X13/P13)*100 -> 60.98278 | Y51: =(Y13/P13)*100 -> 1.5419692 | Z51: =(Z13/CA13)*100 -> 16.64576 | AA51: =(AA13/Z13)*100 -> 58.116704 | AB51: =(AB13/Z13)*100 -> 28.857854 | AC51: =(AC13/Z13)*100 -> 12.997788 | AD51: =(AD13/CA13)*100 -> 0.37287238 | AE51: =(AE13/AD13)*100 -> 69.753086 | AF51: =(AF13/AD13)*100 -> 15.740741 | AG51: =(AG13/AD13)*100 -> 15.740741 | AH51: =(AH13/CA13)*100 -> 4.43534 | AI51: =(AI13/AH13)*100 -> 4.1255838 | AJ51: =(AJ13/AH13)*100 -> 9.8598858 | AK51: =(AK13/AH13)*100 -> 13.596264 | AL51: =(AL13/AH13)*100 -> 38.427608 | AM51: =(AM13/AH13)*100 -> 8.6663207 | AN51: =(AN13/AH13)*100 -> 0.80435911 | AO51: =(AO13/AH13)*100 -> 6.0197198 | AP51: =(AP13/AH13)*100 -> 4.6185781 | AQ51: =(AQ13/AH13)*100 -> 13.907628 | AR51: =(AR13/CA13)*100 -> 12.288677 | AS51: =(AS13/AR13)*100 -> 4.0269713 | AT51: =(AT13/AR13)*100 -> 1.6857089 | AU51: =(AU13/AR13)*100 -> 1.2923768 | AV51: =(AV13/AR13)*100 -> 4.4015733 | AW51: =(AW13/AR13)*100 -> 5.65649 | AX51: =(AX13/AR13)*100 -> 8.1288631 | AY51: =(AY13/AR13)*100 -> 12.755198 | AZ51: =(AZ13/AR13)*100 -> 55.946807 | BA51: =(BA13/AR13)*100 -> 6.1622027 | BB51: =(BB13/CA13)*100 -> 12.644287 | BC51: =(BC13/BB13)*100 -> 7.2176208 | BD51: =(BD13/BB13)*100 -> 9.9754255 | BE51: =(BE13/BB13)*100 -> 1.7930281 | BF51: =(BF13/BB13)*100 -> 9.3656139 | BG51: =(BG13/BB13)*100 -> 12.78784 | BH51: =(BH13/BB13)*100 -> 8.246109 | BI51: =(BI13/BB13)*100 -> 11.813962 | BJ51: =(BJ13/BB13)*100 -> 22.217166 | BK51: =(BK13/BB13)*100 -> 16.592336 | BL51: =(BL13/CA13)*100 -> 4.1706467 | BM51: =(BM13/BL13)*100 -> 2.1247241 | BN51: =(BN13/BL13)*100 -> 3.504415 | BO51: =(BO13/BL13)*100 -> 0.33112583 | BP51: =(BP13/BL13)*100 -> 9.1335541 | BQ51: =(BQ13/BL13)*100 -> 1.7384106 | BR51: =(BR13/BL13)*100 -> 27.704194 | BS51: =(BS13/BL13)*100 -> 21.633554 | BT51: =(BT13/BL13)*100 -> 33.664459 | BU51: =(BU13/CA13)*100 -> 10.37598 | BV51: =(BV13/BU13)*100 -> 20.042147 | BW51: =(BW13/BU13)*100 -> 1.0869565 | BX51: =(BX13/BU13)*100 -> 0.088731145 | BY51: =(BY13/BU13)*100 -> 53.349601 | BZ51: =(BZ13/BU13)*100 -> 25.454747
... A76: Y2062 | B76: =(B38/CA38)*100 -> 10.18003 | C76: =(C38/B38)*100 -> 2.1131302 | D76: =(D38/B38)*100 -> 40.553511 | E76: =(E38/B38)*100 -> 6.5195948 | F76: =(F38/B38)*100 -> 2.3274783 | G76: =(G38/B38)*100 -> 26.089761 | H76: =(H38/B38)*100 -> 13.519102 | I76: =(I38/B38)*100 -> 0.56716871 | J76: =(J38/B38)*100 -> 1.04139 | K76: =(K38/B38)*100 -> 2.993285 | L76: =(L38/B38)*100 -> 4.2812702 | M76: =(M38/CA38)*100 -> 0.61542086 | N76: =(N38/M38)*100 -> 99.372451 | O76: =(O38/M38)*100 -> 0.62754942 | P76: =(P38/CA38)*100 -> 34.673085 | Q76: =(Q38/P38)*100 -> 0.2973986 | R76: =(R38/P38)*100 -> 2.785188 | S76: =(S38/P38)*100 -> 0.011138524 | T76: =(T38/P38)*100 -> 0.79918912 | U76: =(U38/P38)*100 -> 0.13533307 | V76: =(V38/P38)*100 -> 3.6205773 | W76: =(W38/P38)*100 -> 2.8720685 | X76: =(X38/P38)*100 -> 89.125459 | Y76: =(Y38/P38)*100 -> 0.354762 | Z76: =(Z38/CA38)*100 -> 33.103926 | AA76: =(AA38/Z38)*100 -> 50.154873 | AB76: =(AB38/Z38)*100 -> 9.1774533 | AC76: =(AC38/Z38)*100 -> 40.668257 | AD76: =(AD38/CA38)*100 -> 0.2703449 | AE76: =(AE38/AD38)*100 -> 61.857143 | AF76: =(AF38/AD38)*100 -> 29.785714 | AG76: =(AG38/AD38)*100 -> 8.4285714 | AH76: =(AH38/CA38)*100 -> 2.3730489 | AI76: =(AI38/AH38)*100 -> 1.7495321 | AJ76: =(AJ38/AH38)*100 -> 7.714216 | AK76: =(AK38/AH38)*100 -> 9.4637481 | AL76: =(AL38/AH38)*100 -> 43.844088 | AM76: =(AM38/AH38)*100 -> 13.906746 | AN76: =(AN38/AH38)*100 -> 3.5560257 | AO76: =(AO38/AH38)*100 -> 2.4005208 | AP76: =(AP38/AH38)*100 -> 3.3525917 | AQ76: =(AQ38/AH38)*100 -> 14.028806 | AR76: =(AR38/CA38)*100 -> 3.9700149 | AS76: =(AS38/AR38)*100 -> 0.54477358 | AT76: =(AT38/AR38)*100 -> 1.6197286 | AU76: =(AU38/AR38)*100 -> 0.47667688 | AV76: =(AV38/AR38)*100 -> 4.3484605 | AW76: =(AW38/AR38)*100 -> 1.9067075 | AX76: =(AX38/AR38)*100 -> 2.8746534 | AY76: =(AY38/AR38)*100 -> 6.4594581 | AZ76: =(AZ38/AR38)*100 -> 74.590204 | BA76: =(BA38/AR38)*100 -> 7.1890656 | BB76: =(BB38/CA38)*100 -> 3.9680839 | BC76: =(BC38/BB38)*100 -> 6.7156553 | BD76: =(BD38/BB38)*100 -> 11.460412 | BE76: =(BE38/BB38)*100 -> 1.3966616 | BF76: =(BF38/BB38)*100 -> 15.222152 | BG76: =(BG38/BB38)*100 -> 7.6986715 | BH76: =(BH38/BB38)*100 -> 14.248869 | BI76: =(BI38/BB38)*100 -> 15.733126 | BJ76: =(BJ38/BB38)*100 -> 11.100297 | BK76: =(BK38/BB38)*100 -> 16.453355 | BL76: =(BL38/CA38)*100 -> 2.1241385 | BM76: =(BM38/BL38)*100 -> 1.7545455 | BN76: =(BN38/BL38)*100 -> 1.5454545 | BO76: =(BO38/BL38)*100 -> 1.6181818 | BP76: =(BP38/BL38)*100 -> 7.0363636 | BQ76: =(BQ38/BL38)*100 -> 1.7363636 | BR76: =(BR38/BL38)*100 -> 37.154545 | BS76: =(BS38/BL38)*100 -> 5.5545455 | BT76: =(BT38/BL38)*100 -> 43.590909 | BU76: =(BU38/CA38)*100 -> 8.7215196 | BV76: =(BV38/BU38)*100 -> 1.2531828 | BW76: =(BW38/BU38)*100 -> 2.9668991 | BX76: =(BX38/BU38)*100 -> 0.050924388 | BY76: =(BY38/BU38)*100 -> 79.050149 | BZ76: =(BZ38/BU38)*100 -> 16.681058

Sheet Import-dataset
